Workbook

Sheet README
B2: Apple Inc. (APPL) DCF Valuation Model
B4: Valuation Date | D4: 46174
B5: Methodology | D5: 3-statement model + FCFF DCF
B6: Forecast Period | D6: 2026E-2028E
B7: WACC | D7: 0.0993
B8: Terminal Growth | D8: 0.03
B9: Target Price | D9: 121.29
B10: Current Price | D10: 298
B11: Implied Downside | D11: 0.59
C14: Key Drivers
B16: Margin Assumptions
B17: Working Capital Assumptions
B18: Share Repurchases
B19: Products Growth Assumptions
B20: Services Growth Assumptions
B23: Workbook Structure
B25: Assumptions
B26: Income Statement
B27: Balance Sheet
B28: Cash Flow
B29: Operating Statistics
B30: DCF
B32: Model Checks
B34: Balance Sheet Balances | E34: ✓
B35: Cash Flow Reconciles | E35: ✓
B36: DCF Links Working | E36: ✓
B37: No Circular Refrences | E37: ✓

Sheet Assumptions
C1: 2026E | F1: 2027E | I1: 2028E
A2: Products and Services | B2: Bear | C2: Base | D2: Bull | E2: Bear | F2: Base | G2: Bull | H2: Bear | I2: Base | J2: Bull
A4: iPhone | B4: 0.03 | C4: 0.06 | D4: 0.09 | E4: 0.02 | F4: 0.07 | G4: 0.1 | H4: 0.02 | I4: 0.05 | J4: 0.08
A5: Mac | B5: 0.02 | C5: 0.05 | D5: 0.08 | E5: 0.02 | F5: 0.06 | G5: 0.09 | H5: 0.01 | I5: 0.04 | J5: 0.07
A6: iPad | B6: 0.01 | C6: 0.02 | D6: 0.03 | E6: 0 | F6: 0.04 | G6: 0.07 | H6: 0 | I6: 0.03 | J6: 0.05
A7: Wearables, Home, Accessories | B7: -0.01 | C7: 0.02 | D7: 0.05 | E7: 0 | F7: 0.04 | G7: 0.07 | H7: 0 | I7: 0.03 | J7: 0.05
A8: Services | B8: 0.08 | C8: 0.11 | D8: 0.14 | E8: 0.07 | F8: 0.12 | G8: 0.15 | H8: 0.06 | I8: 0.1 | J8: 0.13
A11: Gross Margin | B11: 2026E | C11: 2027E | D11: 2028E
A12: Product Gross Margin | B12: 0.368 | C12: 0.37 | D12: 0.372
A13: Services Margin | B13: 0.755 | C13: 0.758 | D13: 0.76
A16: Operating Expenses | B16: 2026E | C16: 2027E | D16: 2028E
A17: R&D % as Revenue | B17: 0.085 | C17: 0.089 | D17: 0.092
A18: SG&A % as Revenue | B18: 0.066 | C18: 0.065 | D18: 0.064
B21: 2026E% | C21: 2027E% | D21: 2028E%
A22: Other income/(expense), net | B22: -0.0008 | C22: -0.0008 | D22: -0.0008
A23: Provision for Income Taxes | B23: 0.16 | C23: 0.16 | D23: 0.16
A26: Working Capital | B26: 2026E | C26: 2027E | D26: 2028E
A27: Accounts Receivable % Revenue | B27: 0.095 | C27: 0.095 | D27: 0.094
A28: Vendor non-trade receivable % Revenue | B28: 0.08 | C28: 0.08 | D28: 0.08
A29: Inventory % Product Revenue | B29: 0.018 | C29: 0.017 | D29: 0.017
A30: Accounts Payable % Cost of Sales | B30: 0.31 | C30: 0.31 | D30: 0.31
A31: Deferred Revenue % Services Revenue | B31: 0.08 | C31: 0.08 | D31: 0.08
C34: 2026E | D34: 2027E | E34: 2028E
A36: CapEx | B36: 0.03 | C36: 0.035 | D36: 0.037 | E36: 0.04
A37: Depreciation, Ammortization | B37: ='Cash Flow'!D9/'Income Statement'!D7 -> 0.028109313 | C37: 0.03 | D37: 0.03 | E37: 0.03
A39: PP&E schedule | B39: 2025A | C39: 2026E | D39: 2027E | E39: 2028E
A40: Beginning PP&E | B40: ='Balance Sheet'!C15 -> 49834 | C40: =B43 -> 49834 | D40: =C43 -> 52052.516 | E40: =D43 -> 55402.136
A41: CapEx | B41: 12484 | C41: ='Income Statement'!E7*Assumptions!C36 -> 15529.609 | D41: ='Income Statement'!F7*Assumptions!D36 -> 17705.136 | E41: ='Income Statement'!G7*Assumptions!E36 -> 20300.059
A42: Depreciation and Ammortization | B42: 12484 | C42: ='Income Statement'!E7*Assumptions!C37 -> 13311.094 | D42: ='Income Statement'!F7*Assumptions!D37 -> 14355.515 | E42: ='Income Statement'!G7*Assumptions!E37 -> 15225.044
A43: Ending PP&E | B43: =B40+B41-B42 -> 49834 | C43: =C40+C41-C42 -> 52052.516 | D43: =D40+D41-D42 -> 55402.136 | E43: =E40+E41-E42 -> 60477.151
B44: 2025A | C44: 2026E | D44: 2027E | E44: 2028E
A45: Beginning Equity | B45: ='Balance Sheet'!B40 -> 56950 | C45: ='Balance Sheet'!C40 -> 73733 | D45: =C49 -> 85729.848 | E45: =D49 -> 97495.515
A46: Net Income | B46: 112010 | C46: ='Income Statement'!E24 -> 119968.48 | D46: ='Income Statement'!F24 -> 130729.64 | E46: ='Income Statement'!G24 -> 140391.98
A47: Dividends | B47: 15421 | C47: ='Income Statement'!E24*Assumptions!C58 -> 17995.272 | D47: ='Income Statement'!F24*Assumptions!D58 -> 20916.742 | E47: ='Income Statement'!G24*Assumptions!E58 -> 22462.717
A48: Buyback | B48: 90711 | C48: ='Cash Flow'!E7*Assumptions!C56 -> 89976.358 | D48: ='Cash Flow'!F7*Assumptions!D56 -> 98047.23 | E48: ='Cash Flow'!G7*Assumptions!E56 -> 105293.98
A49: Ending Equity | B49: =B45+B46-B47-B48 -> 62828 | C49: =C45+C46-C47-C48 -> 85729.848 | D49: =D45+D46-D47-D48 -> 97495.515 | E49: =E45+E46-E47-E48 -> 110130.79
A54: Cash Flow | B54: 2025A | C54: 2026E | D54: 2027E | E54: 2028E
A55: Share based compensation expense | B55: ='Cash Flow'!D10/'Income Statement'!D7 -> 0.030908711 | C55: 0.03 | D55: 0.03 | E55: 0.03
A56: Buyback | B56: 0 | C56: 0.75 | D56: 0.75 | E56: 0.75
A57: Markatable securities | B57: -0.06 | C57: -0.086 | D57: -0.086 | E57: -0.086
...

Sheet Income Statement
B1: In Millions, except no. of Shares which are reflected in Thousands, and per-share amount
C2: Years ended
B3: 2023A | C3: 2024A | D3: 2025A | E3: 2026E | F3: 2027E | G3: 2028E
A4: Net Sales:
A5: Product | B5: 298085 | C5: 294866 | D5: 307003 | E5: ='Operating Statistics'!E40+'Operating Statistics'!E41+'Operating Statistics'!E42+'Operating Statistics'!E43 -> 322537.74 | F5: ='Operating Statistics'!F40+'Operating Statistics'!F41+'Operating Statistics'!F42+'Operating Statistics'!F43 -> 342811.95 | G5: ='Operating Statistics'!G40+'Operating Statistics'!G41+'Operating Statistics'!G42+'Operating Statistics'!G43 -> 358225.73
A6: Services | B6: 85200 | C6: 96169 | D6: 109158 | E6: ='Operating Statistics'!E44 -> 121165.38 | F6: ='Operating Statistics'!F44 -> 135705.23 | G6: ='Operating Statistics'!G44 -> 149275.75
A7: Total Net Sales | B7: 383285 | C7: 391035 | D7: 416161 | E7: =E5+E6 -> 443703.12 | F7: =F5+F6 -> 478517.18 | G7: =G5+G6 -> 507501.48
A9: Cost of Sales:
A10: Products | B10: 189282 | C10: 185233 | D10: 194116 | E10: =E5*(1-Assumptions!B12) -> 203843.85 | F10: =F5*(1-Assumptions!C12) -> 215971.53 | G10: =G5*(1-Assumptions!D12) -> 224965.76
A11: Services | B11: 24855 | C11: 25119 | D11: 26844 | E11: =E6*(1-Assumptions!B13) -> 29685.518 | F11: =F6*(1-Assumptions!C13) -> 32840.665 | G11: =G6*(1-Assumptions!D13) -> 35826.18
A12: Total Cost of Sales | B12: 214137 | C12: 210352 | D12: 220960 | E12: =E10+E11 -> 233529.37 | F12: =F10+F11 -> 248812.19 | G12: =G10+G11 -> 260791.94
A13: Gross Margin | B13: 169148 | C13: 180683 | D13: 195201 | E13: =E7-E12 -> 210173.75 | F13: =F7-F12 -> 229704.98 | G13: =G7-G12 -> 246709.54
A15: Operating Expenses:
A16: Research and Develpoment | B16: 29915 | C16: 31370 | D16: 34550 | E16: ='Income Statement'!E7*Assumptions!B17 -> 37714.765 | F16: =F7*Assumptions!C17 -> 42588.029 | G16: =G7*Assumptions!D17 -> 46690.136
A17: Selling, general and administrative | B17: 24932 | C17: 26097 | D17: 27601 | E17: =E7*Assumptions!B18 -> 29284.406 | F17: =F7*Assumptions!C18 -> 31103.617 | G17: =G7*Assumptions!D18 -> 32480.095
A18: Total Operating Expenses | B18: 54847 | C18: 57467 | D18: 62151 | E18: =E16+E17 -> 66999.171 | F18: =F16+F17 -> 73691.645 | G18: =G16+G17 -> 79170.231
A20: Operating Income | B20: 114301 | C20: 123216 | D20: 133050 | E20: =E13-E18 -> 143174.58 | F20: =F13-F18 -> 156013.34 | G20: =G13-G18 -> 167539.31
A21: Other income/(expense), net | B21: -565 | C21: 269 | D21: -321 | E21: ='Income Statement'!E7*Assumptions!B22 -> -354.9625 | F21: =F7*Assumptions!C22 -> -382.81374 | G21: =G7*Assumptions!D22 -> -406.00118
A22: Income before provissions for Income taxes | B22: =B20+B21 -> 113736 | C22: =C20+C21 -> 123485 | D22: =D20+D21 -> 132729 | E22: =E20+E21 -> 142819.62 | F22: =F20+F21 -> 155630.52 | G22: =G20+G21 -> 167133.31
A23: Provision for Income taxes | B23: 16741 | C23: 29749 | D23: 20719 | E23: =E22*Assumptions!B23 -> 22851.139 | F23: =F22*Assumptions!C23 -> 24900.884 | G23: =G22*Assumptions!D23 -> 26741.329
A24: Net Income | B24: =B22-B23 -> 96995 | C24: =C22-C23 -> 93736 | D24: =D22-D23 -> 112010 | E24: =E22-E23 -> 119968.48 | F24: =F22-F23 -> 130729.64 | G24: =G22-G23 -> 140391.98
A26: Earnings per share:
A27: Basic | B27: 6.16 | C27: 6.11 | D27: 7.49
A28: Diluted | B28: 6.13 | C28: 6.08 | D28: 7.46
A30: Shares used in computing earnings per share:
A31: Basic | B31: 15744231 | C31: 15343783 | D31: 14948500
A32: Diluted | B32: 15812547 | C32: 15408095 | D32: 15004697

Sheet Balance Sheet
C1: In Millions, except no. of Shares which are reflected in Thousands, and per-share amount
B2: 2024A | C2: 2025A | D2: 2026E | E2: 2027E | F2: 2028E
A3: ASSETS:
A4: Current Assets:
A5: Cash and Cash Equivalents | B5: 29943 | C5: 35934 | D5: ='Cash Flow'!E40 -> 54293.895 | E5: ='Cash Flow'!F40 -> 70560.65 | F5: ='Cash Flow'!G40 -> 86930.732
A6: Marketable Securities | B6: 35228 | C6: 18763 | D6: 18763 | E6: 18763 | F6: 18763
A7: Accounts Receivable, net | B7: 33410 | C7: 39777 | D7: ='Income Statement'!E7*Assumptions!B27 -> 42151.796 | E7: ='Income Statement'!F7*Assumptions!C27 -> 45459.132 | F7: ='Income Statement'!G7*Assumptions!D27 -> 47705.139
A8: Vendor non-trade receivable | B8: 32833 | C8: 33180 | D8: ='Income Statement'!E7*Assumptions!B28 -> 35496.25 | E8: ='Income Statement'!F7*Assumptions!C28 -> 38281.374 | F8: ='Income Statement'!G7*Assumptions!D28 -> 40600.118
A9: Inventories | B9: 7286 | C9: 5718 | D9: ='Income Statement'!E5*Assumptions!B29 -> 5805.6793 | E9: ='Income Statement'!F5*Assumptions!C29 -> 5827.8032 | F9: ='Income Statement'!G5*Assumptions!D29 -> 6089.8374
A10: Other current asset | B10: 14287 | C10: 14585 | D10: 14585 | E10: 14585 | F10: 14585
A11: Total current asset | B11: 152987 | C11: 147957 | D11: =D5+D6+D7+D8+D9+D10 -> 171095.62 | E11: =E5+E6+E7+E8+E9+E10 -> 193476.96 | F11: =F5+F6+F7+F8+F9+F10 -> 214673.83
A13: Non- current assets:
A14: Marketable Securites | B14: 91479 | C14: 77723 | D14: 77723 | E14: 77723 | F14: 77723
A15: Property, plant and equivament, net | B15: 45680 | C15: 49834 | D15: =Assumptions!C43 -> 52052.516 | E15: =Assumptions!D43 -> 55402.136 | F15: =Assumptions!E43 -> 60477.151 | J15: =J14-J13 -> 0
A16: Other non-current asset | B16: 74834 | C16: 83727 | D16: =C16-8029.24 -> 75697.76 | E16: =C16-13890.76 -> 69836.24 | F16: =C16-20483.08 -> 63243.92
A17: Total non- current asset | B17: 211993 | C17: 211284 | D17: =D14+D15+D16 -> 205473.28 | E17: =E14+E15+E16 -> 202961.38 | F17: =F14+F15+F16 -> 201444.07
A18: Total asset | B18: 364980 | C18: 359241 | D18: =D11+D17 -> 376568.9 | E18: =E11+E17 -> 396438.33 | F18: =F11+F17 -> 416117.9
A20: Liabilities and Shareholders Equity:
A21: Current liabilities:
A22: Accounts payable | B22: 68960 | C22: 69860 | D22: ='Income Statement'!E12*Assumptions!B30 -> 72394.105 | E22: ='Income Statement'!F12*Assumptions!C30 -> 77131.78 | F22: ='Income Statement'!G12*Assumptions!D30 -> 80845.501
A23: Other current liabilities | B23: 78304 | C23: 66387 | D23: =C23*(1+2%) -> 67714.74 | E23: =D23*(1+2%) -> 69069.035 | F23: =E23*(1+2%) -> 70450.415
A24: Deferred Revenue | B24: 8249 | C24: 9055 | D24: ='Income Statement'!E6*Assumptions!B31 -> 9693.2304 | E24: ='Income Statement'!F6*Assumptions!C31 -> 10856.418 | F24: ='Income Statement'!G6*Assumptions!D31 -> 11942.06
A25: Commercial Paper | B25: 9967 | C25: 7979 | D25: ='Balance Sheet'!C25 -> 7979 | E25: =D25 -> 7979 | F25: =E25 -> 7979
A26: Term Debt | B26: 10912 | C26: 12350 | D26: =C26 -> 12350 | E26: =D26 -> 12350 | F26: =E26 -> 12350
A27: Total current liabilities | B27: 176392 | C27: 165631 | D27: =D22+D23+D24+D25+D26 -> 170131.08 | E27: =E22+E23+E24+E25+E26 -> 177386.23 | F27: =F22+F23+F24+F25+F26 -> 183566.98
A29: Non-current liabilities:
A30: Term Debt | B30: 85750 | C30: 78328 | D30: =C30 -> 78328 | E30: =C30 -> 78328 | F30: =E30 -> 78328
A31: Other non-current liabilities | B31: 45888 | C31: 41549 | D31: =C31*(1+2%) -> 42379.98 | E31: =D31*(1+2%) -> 43227.58 | F31: =E31*(1+2%) -> 44092.131
A32: Total non-current liabilities | B32: 131638 | C32: 119877 | D32: =D30+D31 -> 120707.98 | E32: =E30+E31 -> 121555.58 | F32: =F30+F31 -> 122420.13
A33: Total liabilities | B33: 308030 | C33: 285508 | D33: =D27+D32 -> 290839.06 | E33: =E27+E32 -> 298941.81 | F33: =F27+F32 -> 305987.11
A35: Shareholders' equity:
A36: Common stock and additional paid in capital, $0.00001 par value: 50,400,000 shares | B36: 83276 | C36: 93568 | D36: 93568 | E36: 93568 | F36: 93568
A37: authorized; 14,773,260 and 15,116,786 shares issued and outstanding, respectively
A38: Accumulated deficit | B38: -19154 | C38: -14264 | D38: -14264 | E38: -14264 | F38: -14264
A39: Accumulated other comprehensive loss | B39: -7172 | C39: 5571 | D39: 5571 | E39: 5571 | F39: 5571
A40: Total shareholders' equity | B40: 56950 | C40: 73733 | D40: =Assumptions!C49 -> 85729.848 | E40: =Assumptions!D49 -> 97495.515 | F40: =Assumptions!E49 -> 110130.79
A41: Total liabilities and shareholders' equity | B41: 364980 | C41: 359241 | D41: =D33+D40 -> 376568.9 | E41: =E33+E40 -> 396437.33 | F41: =F33+F40 -> 416117.9

Sheet Cash Flow
C1: In Millions
C2: Years ended
B3: 2023A | C3: 2024A | D3: 2025A | E3: 2026E | F3: 2027E | G3: 2028E
A4: Cash, cash equivalents, and restricted cash and cash equivalents, beginning balances | B4: 24977 | C4: 30767 | D4: 29943 | E4: =D40 -> 35934 | F4: =E40 -> 54293.895 | G4: =F40 -> 70560.65
A6: Operating activities:
A7: Net income | B7: 96995 | C7: 93736 | D7: 112010 | E7: ='Income Statement'!E24 -> 119968.48 | F7: ='Income Statement'!F24 -> 130729.64 | G7: ='Income Statement'!G24 -> 140391.98
A8: Adjustment to reconcile net income to cash generated by operating activities:
A9: Depreciation and Amortization | B9: 11519 | C9: 11445 | D9: 11698 | E9: =Assumptions!C42 -> 13311.094 | F9: =Assumptions!D42 -> 14355.515 | G9: =Assumptions!E42 -> 15225.044
A10: Share-based compensation expense | B10: 10833 | C10: 11688 | D10: 12863 | E10: ='Income Statement'!E7*Assumptions!C55 -> 13311.094 | F10: ='Income Statement'!F7*Assumptions!D55 -> 14355.515 | G10: ='Income Statement'!G7*Assumptions!E55 -> 15225.044
A11: Other | B11: -2227 | C11: -2266 | D11: -89 | E11: -89 | F11: -89 | G11: -89
A12: Changes in operating asset and liabilities
A13: Accounts receivable, net | B13: -1688 | C13: -3788 | D13: -6682 | E13: ='Balance Sheet'!C7-'Balance Sheet'!D7 -> -2374.7964 | F13: ='Balance Sheet'!D7-'Balance Sheet'!E7 -> -3307.3355 | G13: ='Balance Sheet'!E7-'Balance Sheet'!F7 -> -2246.007
A14: Vendor non-trade receivable | B14: 1271 | C14: -1356 | D14: -347 | E14: ='Balance Sheet'!C8-'Balance Sheet'!D8 -> -2316.2496 | F14: ='Balance Sheet'!D8-'Balance Sheet'!E8 -> -2785.1246 | G14: ='Balance Sheet'!E8-'Balance Sheet'!F8 -> -2318.744
A15: Inventories | B15: -1618 | C15: -1046 | D15: 1400 | E15: ='Balance Sheet'!C9-'Balance Sheet'!D9 -> -87.67932 | F15: ='Balance Sheet'!D9-'Balance Sheet'!E9 -> -22.123871 | G15: ='Balance Sheet'!E9-'Balance Sheet'!F9 -> -262.03422
A16: Other current and non-current assets | B16: -5684 | C16: -11731 | D16: -9197 | E16: -8176.75 | F16: -8355.7 | G16: -6955.92
A17: Accounts payable | B17: -1889 | C17: 6020 | D17: 902 | E17: ='Balance Sheet'!D22-'Balance Sheet'!C22 -> 2534.1046 | F17: ='Balance Sheet'!E22-'Balance Sheet'!D22 -> 4737.6757 | G17: ='Balance Sheet'!F22-'Balance Sheet'!E22 -> 3713.7204
A18: Other current and non-current liabilities | B18: 3031 | C18: 15552 | D18: -11076 | E18: 11863.84 | F18: 9399.8 | G18: 7825.76
A19: Cash generated by operating activities | B19: 110543 | C19: 118254 | D19: 111482 | E19: =E7+E9+E10+E11+E13+E14+E15+E16+E17+E18 -> 147944.13 | F19: =F7+F9+F10+F11+F13+F14+F15+F16+F17+F18 -> 159018.86 | G19: =G7+G9+G10+G11+G13+G14+G15+G16+G17+G18 -> 170509.84
A21: Investing activities:
A22: Purchase of Marketable securities | B22: -29513 | C22: -48656 | D22: -24407 | E22: 0 | F22: 0 | G22: 0
A23: Proceeds from maturities of marketable securities | B23: 39686 | C23: 51211 | D23: 40907 | E23: 0 | F23: 0 | G23: 0
A24: Proceeds from sale of marketable securities | B24: 5828 | C24: 11135 | D24: 12890 | E24: 9951 | F24: 9951 | G24: 9951
A25: Payments for acquisition of property, plant and equipment | B25: -10959 | C25: -9447 | D25: -12715 | E25: =-Assumptions!C41 -> -15529.609 | F25: =-Assumptions!D41 -> -17705.136 | G25: =-Assumptions!E41 -> -20300.059
A26: Others | B26: -1337 | C26: -1308 | D26: -1480 | E26: -1480 | F26: -1480 | G26: -1480
A27: Cash generated by investing activities | B27: 3705 | C27: 2935 | D27: 15195 | E27: =E22+E23+E24+E25+E26 -> -7058.6092 | F27: =F22+F23+F24+F25+F26 -> -9234.1356 | G27: =G22+G23+G24+G25+G26 -> -11829.059
A29: Financing activities:
A30: Payments for taxes related to net share settlement and equity awards | B30: -5431 | C30: -5441 | D30: -5960 | E30: -5960 | F30: -5960 | G30: -5960
A31: Payments for dividends and dividends equivalents | B31: -15025 | C31: -15234 | D31: -15421 | E31: =-E7*Assumptions!C58 -> -17995.272 | F31: =-F7*Assumptions!D58 -> -20916.742 | G31: =-G7*Assumptions!E58 -> -22462.717
A32: Repurchases of common stock | B32: -77550 | C32: -94949 | D32: -90711 | E32: =-Assumptions!C48 -> -89976.358 | F32: =-Assumptions!D48 -> -98047.23 | G32: =-Assumptions!E48 -> -105293.98
A33: Proceeds from issuance of term debt, net | B33: 5228 | C33: -- | D33: 4481 | E33: 4481 | F33: 4481 | G33: 4481
A34: Repayments of term debt | B34: -11151 | C34: -9958 | D34: -10932 | E34: -10932 | F34: -10932 | G34: -10932
A35: Proceeds from /(Repayments of) commercial paper, net | B35: -3978 | C35: 3960 | D35: -2032 | E35: -2032 | F35: -2032 | G35: -2032
A36: Other | B36: -581 | C36: -361 | D36: -111 | E36: -111 | F36: -111 | G36: -111
A37: Cash used in Financing activities | B37: -108488 | C37: -121983 | D37: -120686 | E37: =E30+E31+E32+E33+E34+E35+E36 -> -122525.63 | F37: =F30+F31+F32+F33+F34+F35+F36 -> -133517.97 | G37: =G30+G31+G32+G33+G34+G35+G36 -> -142310.7
A39: Increase/(Decrease) in cash, cash equivalents, and restricted cash and cash equivalents | B39: 5760 | C39: -794 | D39: 5991 | E39: =E19+E27+E37 -> 18359.895 | F39: =F19+F27+F37 -> 16266.754 | G39: =G19+G27+G37 -> 16370.083
A40: Cash, cash equivalents, and restricted cash and cash equivalents, ending balances | B40: 30737 | C40: 29943 | D40: 35934 | E40: =E4+E39 -> 54293.895 | F40: =F4+F39 -> 70560.65 | G40: =G4+G39 -> 86930.732
A42: Supplemental cash flow disclosure:
A43: Cash paid for income taxes, net | B43: 18679 | C43: 26102 | D43: 43369

Sheet Operating Statistics
C1: Segment Operating Performance
D2: ($, in Millions)
C3: 2025
B4: Americas | C4: Europe | D4: Greater China | E4: Japan | F4: Rest of Asia Pacific | G4: Corporate | H4: Total
A5: Net Sales | B5: 178353 | C5: 111030 | D5: 64377 | E5: 28703 | F5: 33696 | G5: -- | H5: =B5+C5+D5+E5+F5 -> 416159
A6: Cost of Sales | B6: -95699 | C6: -58617 | D6: -35141 | E6: -13779 | F6: -17724 | G6: -- | H6: =B6+C6+D6+E6+F6 -> -220960
A7: Research and Development | B7: -- | C7: -- | D7: -- | E7: -- | F7: -- | G7: -34550 | H7: =G7 -> -34550
A8: Selling and Marketing | B8: -10174 | C8: -4676 | D8: -2319 | E8: -969 | F8: -1386 | G8: -- | H8: =B8+C8+D8+E8+F8 -> -19524
A9: General and Administrative | B9: -- | C9: -- | D9: -- | E9: -- | F9: -- | G9: -8077 | H9: =G9 -> -8077
A10: Operating income/loss | B10: =B5+B6+B8 -> 72480 | C10: =C5+C6+C8 -> 47737 | D10: =D5+D6+D8 -> 26917 | E10: =E5+E6+E8 -> 13955 | F10: =F5+F6+F8 -> 14586 | G10: =G7+G9 -> -42627 | H10: =H5+H6+H7+H8+H9 -> 133048
C14: 2024
B15: Americas | C15: Europe | D15: Greater China | E15: Japan | F15: Rest of Asia Pacific | G15: Corporate | H15: Total
A16: Net Sales | B16: 167045 | C16: 101328 | D16: 66952 | E16: 25052 | F16: 30658 | H16: =B16+C16+D16+E16+F16+G16 -> 391035
A17: Cost of Sales | B17: -89587 | C17: -55197 | D17: -37519 | E17: -11744 | F17: -16305 | H17: =B17+C17+D17+E17+F17+G17 -> -210352
A18: Research and Development | G18: -31370 | H18: =B18+C18+D18+E18+F18+G18 -> -31370
A19: Selling and Marketing | B19: -9802 | C19: -4341 | D19: -2351 | E19: -854 | F19: -1291 | H19: =B19+C19+D19+E19+F19+G19 -> -18639
A20: General and Administrative | G20: -7458 | H20: =B20+C20+D20+E20+F20+G20 -> -7458
A21: Operating income/loss | B21: =B16+B17+B18+B19+B20 -> 67656 | C21: =C16+C17+C18+C19+C20 -> 41790 | D21: =D16+D17+D18+D19+D20 -> 27082 | E21: =E16+E17+E18+E19+E20 -> 12454 | F21: =F16+F17+F18+F19+F20 -> 13062 | G21: =G16+G17+G18+G19+G20 -> -38828 | H21: =H16+H17+H18+H19+H20 -> 123216
C25: 2023
B26: Americas | C26: Europe | D26: Greater China | E26: Japan | F26: Rest of Asia Pacific | G26: Corporate | H26: Total
A27: Net Sales | B27: 162560 | C27: 94294 | D27: 72559 | E27: 24257 | F27: 29615 | H27: =B27+C27+D27+E27+F27+G27 -> 383285
A28: Cost of Sales | B28: -92394 | C28: -54101 | D28: -39787 | E28: -11542 | F28: -16313 | H28: =B28+C28+D28+E28+F28+G28 -> -214137
A29: Research and Development | G29: -29915 | H29: =B29+C29+D29+E29+F29+G29 -> -29915
A30: Selling and Marketing | B30: -9658 | C30: -4095 | D30: -2444 | E30: -827 | F30: -1236 | H30: =B30+C30+D30+E30+F30+G30 -> -18260
A31: General and Administrative | G31: -6672 | H31: =B31+C31+D31+E31+F31+G31 -> -6672
A32: Operating income/loss | B32: =B27+B28+B29+B30+B31 -> 60508 | C32: =C27+C28+C29+C30+C31 -> 36098 | D32: =D27+D28+D29+D30+D31 -> 30328 | E32: =E27+E28+E29+E30+E31 -> 11888 | F32: =F27+F28+F29+F30+F31 -> 12066 | G32: =G27+G28+G29+G30+G31 -> -36587 | H32: =B32+C32+D32+E32+F32+G32 -> 114301
B36: Products and Services Performance
B37: (Net Sales, $, in Millions)
B39: 2023A | C39: 2024A | D39: 2025A | E39: 2026E | F39: 2027E | G39: 2028E
A40: iPhone | B40: 200583 | C40: 201183 | D40: 209586 | E40: =D40*(1+D51) -> 222161.16 | F40: =E40*(1+E51) -> 237712.44 | G40: =F40*(1+F51) -> 249598.06
A41: Mac | B41: 29357 | C41: 29984 | D41: 33708 | E41: =D41*(1+D52) -> 35393.4 | F41: =E41*(1+E52) -> 37517.004 | G41: =F41*(1+F52) -> 39017.684
A42: iPad | B42: 28300 | C42: 26694 | D42: 28023 | E42: =D42*(1+D53) -> 28583.46 | F42: =E42*(1+E53) -> 29726.798 | G42: =F42*(1+F53) -> 30618.602
A43: Wearables, Home and Accessories | B43: 39845 | C43: 37005 | D43: 35686 | E43: =D43*(1+D54) -> 36399.72 | F43: =E43*(1+E54) -> 37855.709 | G43: =F43*(1+F54) -> 38991.38
A44: Services | B44: 85200 | C44: 96169 | D44: 109158 | E44: =D44*(1+D55) -> 121165.38 | F44: =E44*(1+E55) -> 135705.23 | G44: =F44*(1+F55) -> 149275.75
A45: Total Net Sales | B45: =B40+B41+B42+B43+B44 -> 383285 | C45: =C40+C41+C42+C43+C44 -> 391035 | D45: =D40+D41+D42+D43+D44 -> 416161 | E45: =E40+E41+E42+E43+E44 -> 443703.12 | F45: =F40+F41+F42+F43+F44 -> 478517.18 | G45: =G40+G41+G42+G43+G44 -> 507501.48
B48: Growth %
B50: 2024A | C50: 2025A | D50: 2026E | E50: 2027E | F50: 2028E
A51: iPhone | B51: =(C40/B40)-1 -> 0.0029912804 | C51: =(D40/C40)-1 -> 0.041767943 | D51: =Assumptions!C4 -> 0.06 | E51: =Assumptions!F4 -> 0.07 | F51: =Assumptions!I4 -> 0.05
A52: Mac | B52: =(C41/B41)-1 -> 0.021357768 | C52: =(D41/C41)-1 -> 0.12419957 | D52: =Assumptions!C5 -> 0.05 | E52: =Assumptions!F5 -> 0.06 | F52: =Assumptions!I5 -> 0.04
A53: iPad | B53: =(C42/B42)-1 -> -0.056749117 | C53: =(D42/C42)-1 -> 0.049786469 | D53: =Assumptions!C6 -> 0.02 | E53: =Assumptions!F6 -> 0.04 | F53: =Assumptions!I6 -> 0.03
...

Sheet DCF
B1: 2026E | C1: 2027E | D1: 2028E | L1: Assumptions | M1: Value
A2: EBIT | B2: ='Income Statement'!E20 -> 143174.58 | C2: ='Income Statement'!F20 -> 156013.34 | D2: ='Income Statement'!G20 -> 167539.31 | L2: Risk-free rate | M2: 0.043
A3: Tax Rate | B3: =Assumptions!B23 -> 0.16 | C3: =Assumptions!C23 -> 0.16 | D3: =Assumptions!D23 -> 0.16 | L3: Beta | M3: 1.05
A4: NOPAT | B4: =B2*(1-B3) -> 120266.65 | C4: =C2*(1-C3) -> 131051.2 | D4: =D2*(1-D3) -> 140733.02 | L4: Equity Risk Premium | M4: 0.055
A5: Depreciation and Ammortization | B5: ='Cash Flow'!E9 -> 13311.094 | C5: ='Cash Flow'!F9 -> 14355.515 | D5: ='Cash Flow'!G9 -> 15225.044 | L5: Cost of Equity | M5: =M2+M3*M4 -> 0.10075
A6: CapEx | B6: =-'Cash Flow'!E25 -> 15529.609 | C6: =-'Cash Flow'!F25 -> 17705.136 | D6: =-'Cash Flow'!G25 -> 20300.059 | L6: Cost of Debt | M6: 0.04
A7: Net Working Capital | B7: =C21 -> -754.36891 | C7: =D21 -> -446.26152 | D7: =E21 -> 198.06476 | L7: Debt | M7: ='Balance Sheet'!C25+'Balance Sheet'!C26+'Balance Sheet'!C30 -> 98657
A8: FCFF | B8: =B4+B5-B6-B7 -> 118802.5 | C8: =C4+C5-C6-C7 -> 128147.85 | D8: =D4+D5-D6-D7 -> 135459.94 | L8: Share price | M8: 298
L9: Diluted shares outstanding | M9: ='Income Statement'!D32/1000 -> 15004.697
L10: Equity | M10: =M8*M9 -> 4471399.7
B11: 2025A | C11: 2026E | D11: 2027E | E11: 2028E | L11: Total Capital | M11: =M7+M10 -> 4570056.7
A12: Average Receivable | B12: ='Balance Sheet'!C7 -> 39777 | C12: ='Balance Sheet'!D7 -> 42151.796 | D12: ='Balance Sheet'!E7 -> 45459.132 | E12: ='Balance Sheet'!F7 -> 47705.139 | L12: Weight of Equity | M12: =M10/M11 -> 0.9784123
A13: Vendor Receivable | B13: ='Balance Sheet'!B8 -> 32833 | C13: ='Balance Sheet'!C8 -> 33180 | D13: ='Balance Sheet'!D8 -> 35496.25 | E13: ='Balance Sheet'!E8 -> 38281.374 | L13: Weight of Debt | M13: =M7/M11 -> 0.021587697
A14: Inventory | B14: ='Balance Sheet'!C9 -> 5718 | C14: ='Balance Sheet'!D9 -> 5805.6793 | D14: ='Balance Sheet'!E9 -> 5827.8032 | E14: ='Balance Sheet'!F9 -> 6089.8374 | L14: After tax cost of debt | M14: =M6*(1-Assumptions!B23) -> 0.0336
A15: Other Current Assets | B15: ='Balance Sheet'!B10 -> 14287 | C15: ='Balance Sheet'!C10 -> 14585 | D15: ='Balance Sheet'!D10 -> 14585 | E15: ='Balance Sheet'!E10 -> 14585 | L15: WACC | M15: =M12*M5+(M13*M14) -> 0.099300386
A16: Operating Current Asset | B16: =B12+B13+B14+B15 -> 92615 | C16: =C12+C13+C14+C15 -> 95722.476 | D16: =D12+D13+D14+D15 -> 101368.18 | E16: =E12+E13+E14+E15 -> 106661.35 | L16: Terminal Growth | M16: 0.03
A17: Average Payables | B17: ='Balance Sheet'!C22 -> 69860 | C17: ='Balance Sheet'!D22 -> 72394.105 | D17: ='Balance Sheet'!E22 -> 77131.78 | E17: ='Balance Sheet'!F22 -> 80845.501 | L17: Terminal FCFF | M17: =D8*(1+M16) -> 139523.74
A18: Other Current Liabilities | B18: ='Balance Sheet'!C23 -> 66387 | C18: ='Balance Sheet'!D23 -> 67714.74 | D18: ='Balance Sheet'!E23 -> 69069.035 | E18: ='Balance Sheet'!F23 -> 70450.415 | L18: Terminal Value | M18: =M17/(M15-M16) -> 2013318.3
A19: Operating Current Liabilities | B19: =B17+B18 -> 136247 | C19: =C17+C18 -> 140108.84 | D19: =D17+D18 -> 146200.82 | E19: =E17+E18 -> 151295.92 | L19: Discounted Terminal Value | M19: =M18/(1+M15)^3 -> 1515525.7
A20: NWC | B20: =B16-B19 -> -43632 | C20: =C16-C19 -> -44386.369 | D20: =D16-D19 -> -44832.63 | E20: =E16-E19 -> -44634.566
A21: NWC | C21: =C20-B20 -> -754.36891 | D21: =D20-C20 -> -446.26152 | E21: =E20-D20 -> 198.06476
B23: Discount FCFFs
A24: FCFF | B24: =B8 -> 118802.5 | C24: =C8 -> 128147.85 | D24: =D8 -> 135459.94
A25: Discount Factor | B25: =1/(1+M15)^1 -> 0.90966947 | C25: =1/(1+M15)^2 -> 0.82749855 | D25: =1/(1+M15)^3 -> 0.75275016
A26: PV FCFF | B26: =B24*B25 -> 108071.01 | C26: =C24*C25 -> 106042.16 | D26: =D24*D25 -> 101967.49
B29: Valuation
A30: PV OF 2026 | B30: =B26 -> 108071.01
A31: PV OF 2027 | B31: =C26 -> 106042.16 | G31: Target Price | H31: =B38 -> 121.28736
A32: PV OF 2028 | B32: =D26 -> 101967.49 | G32: Current Price | H32: =M8 -> 298
A33: PV Terminal value | B33: =M19 -> 1515525.7 | G33: Upside | H33: =H31/H32-1 -> -0.59299543
A34: Enterprise Value | B34: =B30+B31+B32+B33 -> 1831606.4
A35: Cash | B35: ='Cash Flow'!G40 -> 86930.732
A36: Debt | B36: ='Balance Sheet'!F25+'Balance Sheet'!F26+'Balance Sheet'!F30 -> 98657
A37: Equity Value | B37: =B34+B35-B36 -> 1819880.1
A38: Target share price | B38: =B37/DCF!M9 -> 121.28736
A41: (Terminal Growth) | B41: Sensitivity Table | D41: (WACC)
A42: =$B$38 -> 121.28736 | B42: 0.1218 | C42: 0.1318 | D42: 0.1418
A43: 0.02 | B43: 83.533247 | C43: 75.919378 | D43: 69.557209
A44: 0.025 | B44: 87.173233 | C44: 78.870595 | D44: 71.991001
A45: 0.03 | B45: 91.209731 | C45: 82.111716 | D45: 74.642485
